Workbook
Name JR_PAGE_ANCHOR_0_1: #REF!
Name Status: #REF!

Sheet Biinding
A1: No | B1: TestID | C1: Channels | D1: Service_Name | E1: Scenarios | F1: Testcase_Type | G1: Test_Case_Description | H1: Sender_Account_Type | I1: Sender_Account | J1: Sender CoS/Account-Classs | K1: Account_Currency | L1: Amount | M1: Fee | N1: Commission | O1: Receiver Amount | P1: Reciever_Account_Type | Q1: Receiver_Account | R1: Receiver_Class_Of_Service | S1: Reciever_Currency | T1: TID | U1: Transaction Date | V1: Status
A2: 1 | B2: TCRT-0001 | D2: Wing to Wing | E2: Perform from PSP KHR to FC USD | F2: Normal | G2: Perform from PSP KHR to FC USD | H2: PSP | I2: ='Wing Bank App'!I5 -> 07782083 | J2: Customer - Current Account Personal - Standard | K2: KHR | L2: ='Wing Bank App'!L5 -> 120000 | M2: 0 | N2: 0 | P2: FC | Q2: ='Wing Bank App'!Q5 -> 103634533 | R2: High Yield Saving - Standard | S2: USD | V2: ='Wing Bank App'!Z5 -> Passed
A3: 2 | B3: TCRT-0002 | D3: Wing to Wing | E3: Perform from FC KHR to PSP USD | F3: Normal | G3: Perform from FC KHR to PSP USD | H3: FC | I3: ='Wing Bank App'!I6 -> 103634567 | J3: High Yield Saving - Standard | K3: KHR | L3: ='Wing Bank App'!L6 -> 120000 | M3: 0 | N3: 0 | P3: PSP | Q3: ='Wing Bank App'!Q6 -> 07782087 | R3: Customer - Current Account Personal - Standard | S3: USD | V3: ='Wing Bank App'!Z6 -> Passed
A4: 3 | B4: TCRT-0003 | D4: Wing to Wing | E4: Perform from PSP USD to FC KHR | F4: Normal | G4: Perform from PSP USD to FC KHR | H4: PSP | I4: ='Wing Bank App'!I7 -> 07782087 | J4: Customer - Current Account Personal - Standard | K4: USD | L4: ='Wing Bank App'!L7 -> 30 | M4: 0 | N4: 0 | P4: FC | Q4: ='Wing Bank App'!Q7 -> 103634567 | R4: High Yield Saving - Standard | S4: KHR | V4: ='Wing Bank App'!Z7 -> Passed
A5: 4 | B5: TCRT-0004 | D5: Wing to Wing | E5: Perform from FC USD to PSP KHR | F5: Normal | G5: Perform from FC USD to PSP KHR | H5: FC | I5: ='Wing Bank App'!I8 -> 103634533 | J5: High Yield Saving - Standard | K5: USD | L5: ='Wing Bank App'!L8 -> 30 | M5: 0 | N5: 0 | P5: PSP | Q5: ='Wing Bank App'!Q8 -> 07782083 | R5: Customer - Current Account Personal - Standard | S5: KHR | V5: ='Wing Bank App'!Z8 -> Passed
A6: 5 | B6: TCRT-0005 | D6: Wing to Wing | E6: Perform from PSP KHR to PSP USD | F6: Normal | G6: Perform from PSP KHR to PSP USD | H6: PSP | I6: ='Wing Bank App'!I9 -> 07782083 | J6: Customer - Current Account Personal - Standard | K6: KHR | L6: ='Wing Bank App'!L9 -> 120000 | M6: 0 | N6: 0 | P6: PSP | Q6: ='Wing Bank App'!Q9 -> 07782087 | R6: Customer - Current Account Personal - Standard | S6: USD | V6: ='Wing Bank App'!Z9 -> Passed
A7: 6 | B7: TCRT-0006 | D7: Wing to Wing | E7: Perform from FC KHR to FC USD | F7: Normal | G7: Perform from FC KHR to FC USD | H7: FC | I7: ='Wing Bank App'!I10 -> 103634567 | J7: High Yield Saving - Standard | K7: KHR | L7: ='Wing Bank App'!L10 -> 120000 | M7: 0 | N7: 0 | P7: FC | Q7: ='Wing Bank App'!Q10 -> 103634533 | R7: High Yield Saving - Standard | S7: USD | V7: ='Wing Bank App'!Z10 -> Passed
A8: 7 | B8: TCRT-0007 | D8: Wing to Wing | E8: Perform from PSP USD to PSP KHR | F8: Normal | G8: Perform from PSP USD to PSP KHR | H8: PSP | I8: ='Wing Bank App'!I11 -> 07782087 | J8: Customer - Current Account Personal - Standard | K8: USD | L8: ='Wing Bank App'!L11 -> 30 | M8: 0 | N8: 0 | P8: PSP | Q8: ='Wing Bank App'!Q11 -> 07782083 | R8: Customer - Current Account Personal - Standard | S8: KHR | V8: ='Wing Bank App'!Z11 -> Passed
A9: 8 | B9: TCRT-0008 | D9: Wing to Wing | E9: Perform from FC USD to FC KHR | F9: Normal | G9: Perform from FC USD to FC KHR | H9: FC | I9: ='Wing Bank App'!I12 -> 103634533 | J9: Customer - Current Account Personal - Standard | K9: USD | L9: ='Wing Bank App'!L12 -> 30 | M9: 0 | N9: 0 | P9: FC | Q9: ='Wing Bank App'!Q12 -> 103634567 | R9: High Yield Saving - Standard | S9: KHR | V9: ='Wing Bank App'!Z12 -> Passed
A10: 9 | B10: TCRT-0009 | D10: Wing to Wing | E10: Perform from PSP USD to FC USD | F10: Normal | G10: Perform from PSP USD to FC USD | H10: PSP | I10: ='Wing Bank App'!I13 -> 07782087 | J10: High Yield Saving - Standard | K10: USD | L10: ='Wing Bank App'!L13 -> 1 | M10: 0 | N10: 0 | P10: FC | Q10: ='Wing Bank App'!Q13 -> 103634533 | R10: High Yield Saving - Standard | S10: USD | V10: ='Wing Bank App'!Z13 -> Passed
A11: 10 | B11: TCRT-0010 | D11: Wing to Wing | E11: Perform from PSP KHR to FC KHR | F11: Normal | G11: Perform from PSP KHR to FC KHR | H11: PSP | I11: ='Wing Bank App'!I14 -> 07782083 | J11: Customer - Current Account Personal - Standard | K11: KHR | L11: ='Wing Bank App'!L14 -> 4000 | M11: 0 | N11: 0 | P11: FC | Q11: ='Wing Bank App'!Q14 -> 103634567 | R11: High Yield Saving - Standard | S11: KHR | V11: ='Wing Bank App'!Z14 -> Passed
A12: 11 | B12: TCRT-0011 | D12: Wing to Wing | E12: Perform from FC USD to PSP USD | F12: Normal | G12: Perform from FC USD to PSP USD | H12: FC | I12: ='Wing Bank App'!I15 -> 103634533 | J12: High Yield Saving - Standard | K12: USD | L12: ='Wing Bank App'!L15 -> 1 | M12: 0 | N12: 0 | P12: PSP | Q12: ='Wing Bank App'!Q15 -> 07782087 | R12: Customer - Current Account Personal - Standard | S12: USD | V12: ='Wing Bank App'!Z15 -> Passed
A13: 12 | B13: TCRT-0012 | D13: Wing to Wing | E13: Perform from FC KHR to PSP KHR | F13: Normal | G13: Perform from FC KHR to PSP KHR | H13: FC | I13: ='Wing Bank App'!I16 -> 103634567 | J13: High Yield Saving - Standard | K13: KHR | L13: ='Wing Bank App'!L16 -> 4000 | M13: 0 | N13: 0 | P13: PSP | Q13: ='Wing Bank App'!Q16 -> 07782083 | R13: Customer - Current Account Personal - Standard | S13: KHR | V13: ='Wing Bank App'!Z16 -> Passed
... A21: 20 | B21: TCRT-0020 | D21: Code to Wing | E21: Perform code to non-Wing to FC USD that performed wwl from PSP KHR (cross currency) | F21: Normal | G21: Perform code to wing to FC USD that performed wwl from PSP KHR (cross currency) | H21: PSP | I21: ='Wing Bank App'!I24 -> 07782083 | J21: Customer - Current Account Personal - Standard | K21: KHR | L21: ='Wing Bank App'!L24 -> 120000 | M21: 0 | N21: 0 | P21: FC | Q21: ='Wing Bank App'!Q24 -> 103634533 | R21: High Yield Saving - Standard | S21: USD | V21: ='Wing Bank App'!Z24 -> Passed
A22: 21 | B22: TCRT-0021 | D22: PTU Pinless | E22: Peform from PSP USD to Smart | F22: Normal | G22: Peform from PSP USD to Smart | H22: PSP | I22: ='Wing Bank App'!I25 -> 07782087 | J22: Customer - Current Account Personal - Standard | K22: USD | M22: 0 | N22: 0 | O22: ='Wing Bank App'!O25 -> 1 | P22: Phone Number | Q22: ='Wing Bank App'!Q25 -> 098229845 | R22: Smart | S22: USD | V22: ='Wing Bank App'!Z25 -> Passed
A23: 22 | B23: TCRT-0022 | D23: PTU Pinless | E23: Peform from FC KHR to Smart (cross currency) | F23: Normal | G23: Peform from FC KHR to Smart (cross currency) | H23: FC | I23: ='Wing Bank App'!I26 -> 103634567 | J23: High Yield Saving - Standard | K23: KHR | M23: 0 | N23: 0 | O23: ='Wing Bank App'!O26 -> 1 | P23: Phone Number | Q23: ='Wing Bank App'!Q26 -> 098229845 | R23: Smart | S23: USD | V23: ='Wing Bank App'!Z26 -> Passed
A24: 23 | B24: TCRT-0023 | D24: PTU Pinless | E24: Peform from FC USD to Cellcard | F24: Normal | G24: Peform from FC USD to Cellcard | H24: FC | I24: ='Wing Bank App'!I27 -> 103634533 | J24: High Yield Saving - Standard | K24: USD | M24: 0 | N24: 0 | O24: ='Wing Bank App'!O27 -> 1 | P24: Phone Number | Q24: ='Wing Bank App'!Q27 -> 078731099 | R24: Cellcard | S24: USD | V24: ='Wing Bank App'!Z27 -> Passed
A25: 24 | B25: TCRT-0024 | D25: PTU PIN | E25: Perform from PSP KHR to Smart (cross currency) | F25: Normal | G25: Perform from PSP KHR to Smart (cross currency) | H25: PSP | I25: ='Wing Bank App'!I28 -> 07782083 | J25: Customer - Current Account Personal - Standard | K25: KHR | M25: 0 | N25: 0 | O25: ='Wing Bank App'!O28 -> 1 | P25: Operator | Q25: ='Wing Bank App'!Q28 -> Smart | R25: N/A | S25: USD | V25: ='Wing Bank App'!Z28 -> Passed
A26: 25 | B26: TCRT-0025 | D26: PTU PIN | E26: Perform from FC USD to Cellcard | F26: Normal | G26: Perform from FC USD to Cellcard | H26: FC | I26: ='Wing Bank App'!I29 -> 103634533 | J26: High Yield Saving - Standard | K26: USD | M26: 0 | N26: 0 | O26: ='Wing Bank App'!O29 -> 1 | P26: Operator | Q26: ='Wing Bank App'!Q29 -> Cellcard | R26: N/A | S26: USD | V26: ='Wing Bank App'!Z29 -> Passed
A27: 26 | B27: TCRT-0026 | D27: KHQR(WingBank to customer other bank) | E27: Perform from PSP KHR to customer of other bank USD (scan khqr) (cross currency) | F27: Normal | G27: Perform from PSP KHR to customer of other bank USD (scan khqr) (cross currency) | H27: PSP | I27: ='Wing Bank App'!I30 -> 07782083 | J27: Customer - Current Account Personal - Standard | K27: KHR | M27: 0 | N27: 0 | O27: ='Wing Bank App'!O30 -> 30 | P27: Customer QR OtherBank | Q27: ='Wing Bank App'!Q30 -> 00020101021229450016abaakhppxxx@abaa01090044268570208ABA Bank40390006abaP2P011259D64CDECE0F02090044268575204000053038405402305802KH5909RORN MONY6010Phnom Penh993400131776671446325011318082074463256304E369 | R27: ABA Bank Customer | S27: USD | V27: ='Wing Bank App'!Z30 -> Passed
A28: 27 | B28: TCRT-0027 | D28: KHQR(WingBank to customer other bank) | E28: Perform from FC USD to customer of other bank KHR (scan khqr) (cross currency) | F28: Normal | G28: Perform from FC USD to customer of other bank KHR (scan khqr) (cross currency) | H28: FC | I28: ='Wing Bank App'!I31 -> 103634533 | J28: High Yield Saving - Standard | K28: USD | M28: 0 | N28: 0 | O28: ='Wing Bank App'!O31 -> 120000 | P28: Customer QR OtherBank | Q28: ='Wing Bank App'!Q31 -> 00020101021229450016abaakhppxxx@abaa01096009011050208ABA Bank40390006abaP2P011259D64CDECE0F020960090110552040000530311654061200005802KH5909RORN MONY6010Phnom Penh9934001317766714861950113180820748619563041F76 | R28: ABA Bank Customer | S28: KHR | V28: ='Wing Bank App'!Z31 -> Passed
A29: 28 | B29: TCRT-0028 | D29: QR Pay | E29: Perform from PSP KHR to merchant PSP USD(no point) via scan KHQR of wingPay (cross currency) | F29: Normal | G29: Perform from PSP KHR to merchant PSP USD(no point) via scan KHQR of wingPay (cross currency) | H29: PSP | I29: ='Wing Bank App'!I32 -> 07782083 | J29: Customer - Current Account Personal - Standard | K29: KHR | M29: 0 | N29: 0 | O29: ='Wing Bank App'!O32 -> 30 | P29: Merchant App PSP | Q29: ='Wing Bank App'!Q32 -> 00020101021130510014wing_khqr@wing01065331350207WINGPAY0308MERCHANT5204721153038405802KH5923PMOTest Youhai Ren Shop6010Phnom Penh6105120006304B296 | R29: Retail - Bill Pay Corp I (Fee Free) | S29: USD | V29: ='Wing Bank App'!Z32 -> Passed
A30: 29 | B30: TCRT-0029 | D30: QR Pay | E30: Perform from PSP USD to merchant corp1 FC KHR(have point) via scan KHQR of wingPay (cross currency) | F30: Normal | G30: Perform from PSP USD to merchant corp1 FC KHR(have point) via scan KHQR of wingPay (cross currency) | H30: PSP | I30: ='Wing Bank App'!I33 -> 07782087 | J30: Customer - Current Account Personal - Standard | K30: USD | M30: 3000 | N30: 0 | O30: ='Wing Bank App'!O33 -> 120000 | P30: Merchant App FC | Q30: ='Wing Bank App'!Q33 -> 00020101021130420014wing_khqr@wing01090001342930207WINGPAY5204599953031165802KH5919PMOTEST HAI CAR SOP6010Phnom Penh624401062571730211855959890720715FCCMPY00035927863047A8A | R30: Loyalty - Corp 1 (MDR: 0% + Bronze: 2.5%) | S30: KHR | V30: ='Wing Bank App'!Z33 -> Passed
A31: 30 | B31: TCRT-0030 | D31: QR Pay | E31: Perform from PSP KHR to merchant corp1 FC USD(no point) via scan KHQR of wingpay (cross currency) | F31: Normal | G31: Perform from PSP KHR to merchant corp1 FC USD(no point) via scan KHQR of wingpay (cross currency) | H31: PSP | I31: ='Wing Bank App'!I34 -> 07782083 | J31: Customer - Current Account Personal - Standard | K31: KHR | M31: 0 | N31: 0 | O31: ='Wing Bank App'!O34 -> 30 | P31: Merchant App FC | Q31: ='Wing Bank App'!Q34 -> 00020101021130420014wing_khqr@wing01090001342930207WINGPAY5204599953031165802KH5919PMOTEST HAI CAR SOP6010Phnom Penh624401062571730211855959890720715FCCMPY00035927863047A8A | R31: Loyalty - (MDR: 0% + Standard_low: 0%) | S31: USD | V31: ='Wing Bank App'!Z34 -> Passed
A32: 31 | B32: TCRT-0031 | D32: QR Pay | E32: Perform from FC KHR to merchant PSP USD(no point) via scan KHQR of wingpay (cross currency) | F32: Normal | G32: Perform from FC KHR to merchant PSP USD(no point) via scan KHQR of wingpay (cross currency) | H32: FC | I32: ='Wing Bank App'!I35 -> 103634567 | J32: High Yield Saving - Standard | K32: KHR | M32: 0 | N32: 0 | O32: ='Wing Bank App'!O35 -> 30 | P32: Merchant App PSP | Q32: ='Wing Bank App'!Q35 -> 00020101021130510014wing_khqr@wing01065331350207WINGPAY0308MERCHANT5204721153038405802KH5923PMOTest Youhai Ren Shop6010Phnom Penh6105120006304B296 | R32: Retail - Bill Pay Corp I (Fee Free) | S32: USD | V32: ='Wing Bank App'!Z35 -> Passed
A33: 32 | B33: TCRT-0032 | D33: QR Pay | E33: Perform from FC USD to merchant corp1 FC KHR(have point) via scan KHQR of wingpay (cross currency) | F33: Normal | G33: Perform from FC USD to merchant corp1 FC KHR(have point) via scan KHQR of wingpay (cross currency) | H33: FC | I33: ='Wing Bank App'!I36 -> 103634533 | J33: High Yield Saving - Standard | K33: USD | M33: 3000 | N33: 0 | O33: ='Wing Bank App'!O36 -> 120000 | P33: Merchant App FC | Q33: ='Wing Bank App'!Q36 -> 00020101021130420014wing_khqr@wing01090001342930207WINGPAY5204599953031165802KH5919PMOTEST HAI CAR SOP6010Phnom Penh624401062571730211855959890720715FCCMPY00035927863047A8A | R33: Loyalty - Corp 1 (MDR: 0% + Bronze: 2.5%) | S33: KHR | V33: ='Wing Bank App'!Z36 -> Passed
... A44: 43 | B44: TCRT-0043 | D44: Billpay to Bakong Wallet | E44: Perform Transaction Billpay to Bakong Wallet | F44: Normal | G44: From PSP KHR- Bakong Wallet USD | H44: FC | I44: ='Wing Bank App'!I47 -> 103634567 | J44: High Yield Saving - Standard | K44: KHR | M44: 0 | N44: 0 | O44: ='Wing Bank App'!O47 -> 30 | P44: Bakong wallet | Q44: ='Wing Bank App'!Q47 -> 086938457 | R44: Bakong wallet | S44: USD | V44: ='Wing Bank App'!Z47 -> Passed
A45: 44 | B45: TCRT-0044 | D45: Billpay to PPSHV | E45: Perform Transaction Billpay to PPSHV | F45: Normal | G45: Perform Transaction Billpay to PPSHV from FC USD | H45: FC | I45: ='Wing Bank App'!I48 -> 103634533 | J45: High Yield Saving - Standard | K45: USD | L45: ='Wing Bank App'!L48 -> 1 | M45: 0 | N45: 0 | O45: ='Wing Bank App'!O48 -> 0 | P45: PPSHV | Q45: ='Wing Bank App'!Q48 -> 2CI-8210 | R45: Penh | S45: USD | V45: ='Wing Bank App'!Z48 -> Passed
A46: 45 | B46: TCRT-0045 | D46: Billpay to PPSHV | E46: Perform Transaction Billpay to PPSHV | F46: Normal | G46: Perform Transaction Billpay to PPSHV from PSP USD | H46: PSP | I46: ='Wing Bank App'!I49 -> 07782087 | J46: Customer - Current Account Personal - Standard | K46: USD | L46: ='Wing Bank App'!L49 -> 1 | M46: 0 | N46: 0 | O46: ='Wing Bank App'!O49 -> 0 | P46: PPSHV | Q46: ='Wing Bank App'!Q49 -> 2CI-8210 | R46: Penh | S46: USD | V46: ='Wing Bank App'!Z49 -> Passed
A47: 46 | B47: TCRT-0046 | D47: Cash Out(Scan) | E47: Perform from PSP USD wingbank app to scan KhQR of wcx-POS KHR (no cross currency, amount input based on the sender account currency, and receiver account currency based on sender account currency) | F47: Normal | G47: Perform from PSP USD wingbank app to scan KhQR of wcx-POS KHR (no cross currency, amount input based on the sender account currency, and receiver account currency based on sender account currency) | H47: PSP | I47: ='Wing Bank App'!I50 -> 07782087 | J47: Customer - Current Account Personal - Standard | K47: USD | M47: Free | N47: 0.15 | O47: ='Wing Bank App'!O50 -> 5 | P47: WCX PSP (Agent) | Q47: ='Wing Bank App'!Q50 -> 00751774 | R47: Cash XPress - Standard | S47: USD | V47: ='Wing Bank App'!Z50 -> Passed
A48: 47 | B48: TCRT-0047 | D48: Cash Out(Scan) | E48: Perform from FC KHR wingbank app to scan KHQR of wcx-POS USD (no cross currency, amount input based on the sender account currency, and receiver account currency based on sender account currency) | F48: Normal | G48: Perform from FC KHR wingbank app to scan KHQR of wcx-POS USD (no cross currency, amount input based on the sender account currency, and receiver account currency based on sender account currency) | H48: FC | I48: ='Wing Bank App'!I51 -> 103634567 | J48: High Yield Saving - Standard | K48: KHR | M48: Free | N48: 600 | O48: ='Wing Bank App'!O51 -> 20000 | P48: WCX PSP (Agent) | Q48: ='Wing Bank App'!Q51 -> 00751770 | R48: Cash XPress - Standard | S48: KHR | V48: ='Wing Bank App'!Z51 -> Passed
A49: 48 | B49: TCRT-0048 | D49: Own Account Transfer | E49: Perform from FC USD to PSP KHR (cross currency) | F49: Normal | G49: Perform from FC USD to PSP KHR (cross currency) | H49: FC | I49: ='Wing Bank App'!I52 -> 103634533 | J49: High Yield Saving - Standard | K49: USD | L49: ='Wing Bank App'!L52 -> 30 | M49: 0 | N49: 0 | P49: PSP | Q49: ='Wing Bank App'!Q52 -> 07782083 | R49: Customer - Current Account Personal - Standard | S49: KHR | V49: ='Wing Bank App'!Z52 -> Passed
A50: 49 | B50: TCRT-0049 | D50: Own Account Transfer | E50: Perform from PSP KHR to FC USD (cross currency) | F50: Normal | G50: Perform from PSP KHR to FC USD (cross currency) | H50: PSP | I50: ='Wing Bank App'!I53 -> 07782083 | J50: Customer - Current Account Personal - Standard | K50: KHR | L50: ='Wing Bank App'!L53 -> 120000 | M50: 0 | N50: 0 | P50: FC | Q50: ='Wing Bank App'!Q53 -> 103634533 | R50: High Yield Saving - Standard | S50: USD | V50: ='Wing Bank App'!Z53 -> Passed
A51: 50 | B51: TCRT-0050 | D51: Wing To World | E51: International Remittance - Cash Pickup sacom VND | F51: Normal | G51: Perform International Remittance - Cash Pickup from FC USD | H51: FC | I51: ='Wing Bank App'!I54 -> 103634533 | J51: High Yield Saving - Standard | K51: USD | M51: $4.00 | N51: 0 | O51: ='Wing Bank App'!O54 -> 0 | P51: N/A | Q51: ='Wing Bank App'!Q54 -> N/A | R51: N/A | S51: VND | V51: ='Wing Bank App'!Z54 -> Failed
A52: 51 | B52: TCRT-0051 | D52: Wing To World | E52: International Remittance - Cash Pickup sacom VND | F52: Normal | G52: Perform International Remittance - Cash Pickup from PSP USD | H52: PSP | I52: ='Wing Bank App'!I55 -> 07782087 | J52: Customer - Current Account Personal - Standard | K52: USD | M52: $4.00 | N52: 0 | O52: ='Wing Bank App'!O55 -> 0 | P52: N/A | Q52: ='Wing Bank App'!Q55 -> N/A | R52: N/A | S52: VND | V52: ='Wing Bank App'!Z55 -> Failed
A53: 52 | B53: TCRT-0052 | D53: Transfer to Local Bank via Bakong | E53: Perform Transaction Transfer to Local Bank via Bakong | F53: Normal | G53: Transfer to Local Bank via Bakong From FC USD-Other Bank KHR | H53: FC | I53: ='Wing Bank App'!I56 -> 103634533 | J53: High Yield Saving - Standard | K53: USD | M53: - ៛2,600 | N53: 0 | O53: ='Wing Bank App'!O56 -> 120000 | P53: ABA Bank | Q53: ='Wing Bank App'!Q56 -> 600901105 | R53: ABA Saving Account | S53: KHR | V53: ='Wing Bank App'!Z56 -> Passed
A54: 53 | B54: TCRT-0053 | D54: Transfer to Local Bank via Bakong | E54: Perform Transaction Transfer to Local Bank via Bakong | F54: Normal | G54: Transfer to Local Bank via Bakong From FC KHR-Other Bank USD | H54: FC | I54: ='Wing Bank App'!I57 -> 103634567 | J54: High Yield Saving - Standard | K54: KHR | M54: - $0.65 | N54: 0 | O54: ='Wing Bank App'!O57 -> 30 | P54: ABA Bank | Q54: ='Wing Bank App'!Q57 -> 004426857 | R54: ABA Saving Account | S54: USD | V54: ='Wing Bank App'!Z57 -> Passed
A55: 54 | B55: TCRT-0054 | D55: Transfer to Local Bank via Bakong | E55: Perform Transaction Transfer to Local Bank via Bakong | F55: Normal | G55: Transfer to Local Bank via Bakong From PSP KHR-Other Bank USD | H55: PSP | I55: ='Wing Bank App'!I58 -> 07782083 | J55: Customer - Current Account Personal - Standard | K55: KHR | M55: - $0.65 | N55: 0 | O55: ='Wing Bank App'!O58 -> 30 | P55: ABA Bank | Q55: ='Wing Bank App'!Q58 -> 004426857 | R55: ABA Saving Account | S55: USD | V55: ='Wing Bank App'!Z58 -> Passed
A56: 55 | B56: TCRT-0055 | D56: Transfer to Local Bank via Bakong | E56: Perform Transaction Transfer to Local Bank via Bakong | F56: Normal | G56: Transfer to Local Bank via Bakong From PSP USD-Other Bank KHR | H56: PSP | I56: ='Wing Bank App'!I59 -> 07782087 | J56: Customer - Current Account Personal - Standard | K56: USD | M56: - ៛2,600 | N56: 0 | O56: ='Wing Bank App'!O59 -> 120000 | P56: ABA Bank | Q56: ='Wing Bank App'!Q59 -> 600901105 | R56: ABA Saving Account | S56: KHR | V56: ='Wing Bank App'!Z59 -> Passed
A57: 56 | B57: TCRT-0056 | D57: Wing To Other Banks NCS | E57: Perform Transaction Wing To Other Banks NCS | F57: Normal | G57: From FC USD - Other Bank | H57: FC | I57: ='Wing Bank App'!I60 -> 103634533 | J57: High Yield Saving - Standard | K57: USD | L57: ='Wing Bank App'!L60 -> 2 | M57: Free | N57: 0 | P57: Advanced Bank of Asia Ltd | Q57: ='Wing Bank App'!Q60 -> 004426857 | R57: Mony Rorn | S57: USD | V57: ='Wing Bank App'!Z60 -> Passed
...

Sheet Wing Bank App
B1: Big Rate | C1: Small Rate | D1: Rate Date
A4: No | B4: TestID | C4: Channels | D4: Service_Name | E4: Scenarios | F4: Testcase_Type | G4: Test_Case_Description | H4: Sender_Account_Type | I4: Sender_Account | J4: Sender CoS/Account-Classs | K4: Account_Currency | L4: Amount | M4: Fee | N4: Commission | O4: Receiver Amount | P4: Reciever_Account_Type | Q4: Receiver_Account | R4: Receiver_Class_Of_Service | S4: Reciever_Currency | T4: Exchange Rate | U4: Rate Type | V4: TID | W4: Transaction Date | X4: Expected Result | Y4: Actual Result | Z4: Status | AA4: Testing Type | AB4: Tester | AC4: Hyper Link Reference | AD4: Remark | AE4: Finance Staus | AF4: Finance Comment
A5: 1 | B5: TCRT-0001 | C5: Wing Bank App | D5: Wing to Wing | E5: Perform from PSP KHR to FC USD | F5: Normal | G5: Perform from PSP KHR to FC USD | H5: PSP | I5: =IF(H5="PSP",IF(K5="KHR",'Config Data'!$D$13,'Config Data'!$D$14),IF(H5="FC",IF(K5="KHR",'Config Data'!$D$15,'Config Data'!$D$16))) -> 07782083 | J5: Customer - Current Account Personal - Standard | K5: KHR | L5: =IF(AND(K5="USD",S5="KHR"),30,IF(AND(K5="KHR",S5="USD"),120000,IF(AND(K5="USD",S5="USD"),1,IF(AND(K5="KHR",S5="KHR"),4000,IF(S5="KHR",'Config Data'!$D$21,IF(S5="USD",'Config Data'!$D$23,"")))))) -> 120000 | M5: 0 | N5: 0 | O5: 29.61 | P5: FC | Q5: =IF(P5="PSP",IF(S5="KHR",'Config Data'!$D$13,'Config Data'!$D$14),IF(P5="FC",IF(S5="KHR",'Config Data'!$D$15,'Config Data'!$D$16))) -> 103634533 | R5: High Yield Saving - Standard | S5: USD | T5: 4053 | U5: Big Rate | V5: EYB558038 | W5: 27-08-2026 | 01:49:18 AM | X5: 1-Transaction will be success 2-Amount deducted from the payer to the payee is correct 3-Exchange rate is correct | Y5: As Expected | Z5: Passed | AA5: Automation | AC5: =HYPERLINK("Screenshots/Wing To Wing/TCRT-0001","View Screenshots") -> View Screenshots
A6: 2 | B6: TCRT-0002 | E6: Perform from FC KHR to PSP USD | F6: Normal | G6: Perform from FC KHR to PSP USD | H6: FC | I6: =IF(H6="PSP",IF(K6="KHR",'Config Data'!$D$13,'Config Data'!$D$14),IF(H6="FC",IF(K6="KHR",'Config Data'!$D$15,'Config Data'!$D$16))) -> 103634567 | J6: High Yield Saving - Standard | K6: KHR | L6: =IF(AND(K6="USD",S6="KHR"),30,IF(AND(K6="KHR",S6="USD"),120000,IF(AND(K6="USD",S6="USD"),1,IF(AND(K6="KHR",S6="KHR"),4000,IF(S6="KHR",'Config Data'!$D$21,IF(S6="USD",'Config Data'!$D$23,"")))))) -> 120000 | M6: 0 | N6: 0 | O6: 29.60 | P6: PSP | Q6: =IF(P6="PSP",IF(S6="KHR",'Config Data'!$D$13,'Config Data'!$D$14),IF(P6="FC",IF(S6="KHR",'Config Data'!$D$15,'Config Data'!$D$16))) -> 07782087 | R6: Customer - Current Account Personal - Standard | S6: USD | T6: 4053 | U6: Big Rate | V6: 0002345262398049 | W6: 27-08-2026 | 01:49:51 AM | X6: 1-Transaction will be success 2-Amount deducted from the payer to the payee is correct 3-Exchange rate is correct | Y6: As Expected | Z6: Passed | AA6: Automation | AC6: =HYPERLINK("Screenshots/Wing To Wing/TCRT-0002","View Screenshots") -> View Screenshots
A7: 3 | B7: TCRT-0003 | E7: Perform from PSP USD to FC KHR | F7: Normal | G7: Perform from PSP USD to FC KHR | H7: PSP | I7: =IF(H7="PSP",IF(K7="KHR",'Config Data'!$D$13,'Config Data'!$D$14),IF(H7="FC",IF(K7="KHR",'Config Data'!$D$15,'Config Data'!$D$16))) -> 07782087 | J7: Customer - Current Account Personal - Standard | K7: USD | L7: =IF(AND(K7="USD",S7="KHR"),30,IF(AND(K7="KHR",S7="USD"),120000,IF(AND(K7="USD",S7="USD"),1,IF(AND(K7="KHR",S7="KHR"),4000,IF(S7="KHR",'Config Data'!$D$21,IF(S7="USD",'Config Data'!$D$23,"")))))) -> 30 | M7: 0 | N7: 0 | O7: 121350 | P7: FC | Q7: =IF(P7="PSP",IF(S7="KHR",'Config Data'!$D$13,'Config Data'!$D$14),IF(P7="FC",IF(S7="KHR",'Config Data'!$D$15,'Config Data'!$D$16))) -> 103634567 | R7: High Yield Saving - Standard | S7: KHR | T7: 4045 | U7: Small Rate | V7: EYB558066 | W7: 27-08-2026 | 01:50:25 AM | X7: 1-Transaction will be success 2-Amount deducted from the payer to the payee is correct 3-Exchange rate is correct | Y7: As Expected | Z7: Passed | AA7: Automation | AC7: =HYPERLINK("Screenshots/Wing To Wing/TCRT-0003","View Screenshots") -> View Screenshots
A8: 4 | B8: TCRT-0004 | E8: Perform from FC USD to PSP KHR | F8: Normal | G8: Perform from FC USD to PSP KHR | H8: FC | I8: =IF(H8="PSP",IF(K8="KHR",'Config Data'!$D$13,'Config Data'!$D$14),IF(H8="FC",IF(K8="KHR",'Config Data'!$D$15,'Config Data'!$D$16))) -> 103634533 | J8: High Yield Saving - Standard | K8: USD | L8: =IF(AND(K8="USD",S8="KHR"),30,IF(AND(K8="KHR",S8="USD"),120000,IF(AND(K8="USD",S8="USD"),1,IF(AND(K8="KHR",S8="KHR"),4000,IF(S8="KHR",'Config Data'!$D$21,IF(S8="USD",'Config Data'!$D$23,"")))))) -> 30 | M8: 0 | N8: 0 | O8: 121350 | P8: PSP | Q8: =IF(P8="PSP",IF(S8="KHR",'Config Data'!$D$13,'Config Data'!$D$14),IF(P8="FC",IF(S8="KHR",'Config Data'!$D$15,'Config Data'!$D$16))) -> 07782083 | R8: Customer - Current Account Personal - Standard | S8: KHR | T8: 4045 | U8: Small Rate | V8: 0002345262398163 | W8: 27-08-2026 | 01:50:52 AM | X8: 1-Transaction will be success 2-Amount deducted from the payer to the payee is correct 3-Exchange rate is correct | Y8: As Expected | Z8: Passed | AA8: Automation | AC8: =HYPERLINK("Screenshots/Wing To Wing/TCRT-0004","View Screenshots") -> View Screenshots
A9: 5 | B9: TCRT-0005 | E9: Perform from PSP KHR to PSP USD | F9: Normal | G9: Perform from PSP KHR to PSP USD | H9: PSP | I9: =IF(H9="PSP",IF(K9="KHR",'Config Data'!$D$13,'Config Data'!$D$14),IF(H9="FC",IF(K9="KHR",'Config Data'!$D$15,'Config Data'!$D$16))) -> 07782083 | J9: Customer - Current Account Personal - Standard | K9: KHR | L9: =IF(AND(K9="USD",S9="KHR"),30,IF(AND(K9="KHR",S9="USD"),120000,IF(AND(K9="USD",S9="USD"),1,IF(AND(K9="KHR",S9="KHR"),4000,IF(S9="KHR",'Config Data'!$D$21,IF(S9="USD",'Config Data'!$D$23,"")))))) -> 120000 | M9: 0 | N9: 0 | O9: 29.60 | P9: PSP | Q9: =IF(P9="PSP",IF(S9="KHR",'Config Data'!$D$13,'Config Data'!$D$14),IF(P9="FC",IF(S9="KHR",'Config Data'!$D$15,'Config Data'!$D$16))) -> 07782087 | R9: Customer - Current Account Personal - Standard | S9: USD | T9: 4053 | U9: Big Rate | V9: EYB558094 | W9: 27-08-2026 | 01:51:20 AM | X9: 1-Transaction will be success 2-Amount deducted from the payer to the payee is correct 3-Exchange rate is correct | Y9: As Expected | Z9: Passed | AA9: Automation | AC9: =HYPERLINK("Screenshots/Wing To Wing/TCRT-0005","View Screenshots") -> View Screenshots
A10: 6 | B10: TCRT-0006 | E10: Perform from FC KHR to FC USD | F10: Normal | G10: Perform from FC KHR to FC USD | H10: FC | I10: =IF(H10="PSP",IF(K10="KHR",'Config Data'!$D$13,'Config Data'!$D$14),IF(H10="FC",IF(K10="KHR",'Config Data'!$D$15,'Config Data'!$D$16))) -> 103634567 | J10: High Yield Saving - Standard | K10: KHR | L10: =IF(AND(K10="USD",S10="KHR"),30,IF(AND(K10="KHR",S10="USD"),120000,IF(AND(K10="USD",S10="USD"),1,IF(AND(K10="KHR",S10="KHR"),4000,IF(S10="KHR",'Config Data'!$D$21,IF(S10="USD",'Config Data'!$D$23,"")))))) -> 120000 | M10: 0 | N10: 0 | O10: 29.61 | P10: FC | Q10: =IF(P10="PSP",IF(S10="KHR",'Config Data'!$D$13,'Config Data'!$D$14),IF(P10="FC",IF(S10="KHR",'Config Data'!$D$15,'Config Data'!$D$16))) -> 103634533 | R10: High Yield Saving - Standard | S10: USD | T10: 4053 | U10: Big Rate | V10: 0002345262398263 | W10: 27-08-2026 | 01:51:50 AM | X10: 1-Transaction will be success 2-Amount deducted from the payer to the payee is correct 3-Exchange rate is correct | Y10: As Expected | Z10: Passed | AA10: Automation | AC10: =HYPERLINK("Screenshots/Wing To Wing/TCRT-0006","View Screenshots") -> View Screenshots
A11: 7 | B11: TCRT-0007 | E11: Perform from PSP USD to PSP KHR | F11: Normal | G11: Perform from PSP USD to PSP KHR | H11: PSP | I11: =IF(H11="PSP",IF(K11="KHR",'Config Data'!$D$13,'Config Data'!$D$14),IF(H11="FC",IF(K11="KHR",'Config Data'!$D$15,'Config Data'!$D$16))) -> 07782087 | J11: Customer - Current Account Personal - Standard | K11: USD | L11: =IF(AND(K11="USD",S11="KHR"),30,IF(AND(K11="KHR",S11="USD"),120000,IF(AND(K11="USD",S11="USD"),1,IF(AND(K11="KHR",S11="KHR"),4000,IF(S11="KHR",'Config Data'!$D$21,IF(S11="USD",'Config Data'!$D$23,"")))))) -> 30 | M11: 0 | N11: 0 | O11: 121350 | P11: PSP | Q11: =IF(P11="PSP",IF(S11="KHR",'Config Data'!$D$13,'Config Data'!$D$14),IF(P11="FC",IF(S11="KHR",'Config Data'!$D$15,'Config Data'!$D$16))) -> 07782083 | R11: Customer - Current Account Personal - Standard | S11: KHR | T11: 4045 | U11: Small Rate | V11: EYB558119 | W11: 27-08-2026 | 01:52:18 AM | X11: 1-Transaction will be success 2-Amount deducted from the payer to the payee is correct 3-Exchange rate is correct | Y11: As Expected | Z11: Passed | AA11: Automation | AC11: =HYPERLINK("Screenshots/Wing To Wing/TCRT-0007","View Screenshots") -> View Screenshots
A12: 8 | B12: TCRT-0008 | E12: Perform from FC USD to FC KHR | F12: Normal | G12: Perform from FC USD to FC KHR | H12: FC | I12: =IF(H12="PSP",IF(K12="KHR",'Config Data'!$D$13,'Config Data'!$D$14),IF(H12="FC",IF(K12="KHR",'Config Data'!$D$15,'Config Data'!$D$16))) -> 103634533 | J12: Customer - Current Account Personal - Standard | K12: USD | L12: =IF(AND(K12="USD",S12="KHR"),30,IF(AND(K12="KHR",S12="USD"),120000,IF(AND(K12="USD",S12="USD"),1,IF(AND(K12="KHR",S12="KHR"),4000,IF(S12="KHR",'Config Data'!$D$21,IF(S12="USD",'Config Data'!$D$23,"")))))) -> 30 | M12: 0 | N12: 0 | O12: 121350 | P12: FC | Q12: =IF(P12="PSP",IF(S12="KHR",'Config Data'!$D$13,'Config Data'!$D$14),IF(P12="FC",IF(S12="KHR",'Config Data'!$D$15,'Config Data'!$D$16))) -> 103634567 | R12: High Yield Saving - Standard | S12: KHR | T12: 4045 | U12: Small Rate | V12: 0002345262398360 | W12: 27-08-2026 | 01:52:45 AM | X12: 1-Transaction will be success 2-Amount deducted from the payer to the payee is correct 3-Exchange rate is correct | Y12: As Expected | Z12: Passed | AA12: Automation | AC12: =HYPERLINK("Screenshots/Wing To Wing/TCRT-0008","View Screenshots") -> View Screenshots
A13: 9 | B13: TCRT-0009 | E13: Perform from PSP USD to FC USD | F13: Normal | G13: Perform from PSP USD to FC USD | H13: PSP | I13: =IF(H13="PSP",IF(K13="KHR",'Config Data'!$D$13,'Config Data'!$D$14),IF(H13="FC",IF(K13="KHR",'Config Data'!$D$15,'Config Data'!$D$16))) -> 07782087 | J13: High Yield Saving - Standard | K13: USD | L13: =IF(AND(K13="USD",S13="KHR"),30,IF(AND(K13="KHR",S13="USD"),120000,IF(AND(K13="USD",S13="USD"),1,IF(AND(K13="KHR",S13="KHR"),4000,IF(S13="KHR",'Config Data'!$D$21,IF(S13="USD",'Config Data'!$D$23,"")))))) -> 1 | M13: 0 | N13: 0 | O13: 1.00 | P13: FC | Q13: =IF(P13="PSP",IF(S13="KHR",'Config Data'!$D$13,'Config Data'!$D$14),IF(P13="FC",IF(S13="KHR",'Config Data'!$D$15,'Config Data'!$D$16))) -> 103634533 | R13: High Yield Saving - Standard | S13: USD | U13: N/A | V13: EYB558145 | W13: 27-08-2026 | 01:53:19 AM | X13: 1-Transaction will be success 2-Amount deducted from the payer to the payee is correct 3-Exchange rate is correct | Y13: As Expected | Z13: Passed | AA13: Automation | AC13: =HYPERLINK("Screenshots/Wing To Wing/TCRT-0009","View Screenshots") -> View Screenshots
A14: 10 | B14: TCRT-0010 | E14: Perform from PSP KHR to FC KHR | F14: Normal | G14: Perform from PSP KHR to FC KHR | H14: PSP | I14: =IF(H14="PSP",IF(K14="KHR",'Config Data'!$D$13,'Config Data'!$D$14),IF(H14="FC",IF(K14="KHR",'Config Data'!$D$15,'Config Data'!$D$16))) -> 07782083 | J14: Customer - Current Account Personal - Standard | K14: KHR | L14: =IF(AND(K14="USD",S14="KHR"),30,IF(AND(K14="KHR",S14="USD"),120000,IF(AND(K14="USD",S14="USD"),1,IF(AND(K14="KHR",S14="KHR"),4000,IF(S14="KHR",'Config Data'!$D$21,IF(S14="USD",'Config Data'!$D$23,"")))))) -> 4000 | M14: 0 | N14: 0 | O14: 4000 | P14: FC | Q14: =IF(P14="PSP",IF(S14="KHR",'Config Data'!$D$13,'Config Data'!$D$14),IF(P14="FC",IF(S14="KHR",'Config Data'!$D$15,'Config Data'!$D$16))) -> 103634567 | R14: High Yield Saving - Standard | S14: KHR | U14: N/A | V14: EYB558157 | W14: 27-08-2026 | 01:53:46 AM | X14: 1-Transaction will be success 2-Amount deducted from the payer to the payee is correct 3-Exchange rate is correct | Y14: As Expected | Z14: Passed | AA14: Automation | AC14: =HYPERLINK("Screenshots/Wing To Wing/TCRT-0010","View Screenshots") -> View Screenshots
A15: 11 | B15: TCRT-0011 | E15: Perform from FC USD to PSP USD | F15: Normal | G15: Perform from FC USD to PSP USD | H15: FC | I15: =IF(H15="PSP",IF(K15="KHR",'Config Data'!$D$13,'Config Data'!$D$14),IF(H15="FC",IF(K15="KHR",'Config Data'!$D$15,'Config Data'!$D$16))) -> 103634533 | J15: High Yield Saving - Standard | K15: USD | L15: =IF(AND(K15="USD",S15="KHR"),30,IF(AND(K15="KHR",S15="USD"),120000,IF(AND(K15="USD",S15="USD"),1,IF(AND(K15="KHR",S15="KHR"),4000,IF(S15="KHR",'Config Data'!$D$21,IF(S15="USD",'Config Data'!$D$23,"")))))) -> 1 | M15: 0 | N15: 0 | O15: 1.00 | P15: PSP | Q15: =IF(P15="PSP",IF(S15="KHR",'Config Data'!$D$13,'Config Data'!$D$14),IF(P15="FC",IF(S15="KHR",'Config Data'!$D$15,'Config Data'!$D$16))) -> 07782087 | R15: Customer - Current Account Personal - Standard | S15: USD | U15: N/A | V15: 0002345262398529 | W15: 27-08-2026 | 01:54:13 AM | X15: 1-Transaction will be success 2-Amount deducted from the payer to the payee is correct 3-Exchange rate is correct | Y15: As Expected | Z15: Passed | AA15: Automation | AC15: =HYPERLINK("Screenshots/Wing To Wing/TCRT-0011","View Screenshots") -> View Screenshots
A16: 12 | B16: TCRT-0012 | E16: Perform from FC KHR to PSP KHR | F16: Normal | G16: Perform from FC KHR to PSP KHR | H16: FC | I16: =IF(H16="PSP",IF(K16="KHR",'Config Data'!$D$13,'Config Data'!$D$14),IF(H16="FC",IF(K16="KHR",'Config Data'!$D$15,'Config Data'!$D$16))) -> 103634567 | J16: High Yield Saving - Standard | K16: KHR | L16: =IF(AND(K16="USD",S16="KHR"),30,IF(AND(K16="KHR",S16="USD"),120000,IF(AND(K16="USD",S16="USD"),1,IF(AND(K16="KHR",S16="KHR"),4000,IF(S16="KHR",'Config Data'!$D$21,IF(S16="USD",'Config Data'!$D$23,"")))))) -> 4000 | M16: 0 | N16: 0 | O16: 4000 | P16: PSP | Q16: =IF(P16="PSP",IF(S16="KHR",'Config Data'!$D$13,'Config Data'!$D$14),IF(P16="FC",IF(S16="KHR",'Config Data'!$D$15,'Config Data'!$D$16))) -> 07782083 | R16: Customer - Current Account Personal - Standard | S16: KHR | U16: N/A | V16: 0002345262398579 | W16: 27-08-2026 | 01:54:40 AM | X16: 1-Transaction will be success 2-Amount deducted from the payer to the payee is correct 3-Exchange rate is correct | Y16: As Expected | Z16: Passed | AA16: Automation | AC16: =HYPERLINK("Screenshots/Wing To Wing/TCRT-0012","View Screenshots") -> View Screenshots
A17: 13 | B17: TCRT-0013 | D17: Wing Wei Luy | E17: Perform from PSP USD to Phone Number | F17: Normal | G17: Perform from PSP USD to Phone Number | H17: PSP | I17: =IF(H17="PSP",IF(K17="KHR",'Config Data'!$D$13,'Config Data'!$D$14),IF(H17="FC",IF(K17="KHR",'Config Data'!$D$15,'Config Data'!$D$16))) -> 07782087 | J17: Customer - Current Account Personal - Standard | K17: USD | L17: =IF(K17="KHR",'Config Data'!$D$21,IF(K17="USD",'Config Data'!$D$23,"")) -> 30 | M17: 0.75 | N17: 0 | O17: 30.00 | P17: Phone Number | Q17: ='Config Data'!D$17 -> 077989682 | R17: N/A | S17: N/A | U17: N/A | V17: AYZ539464 | W17: 27-08-2026 | 01:55:09 AM | X17: 1-Transaction will be success 2-Amount deducted from the payer to the payee is correct 3-Exchange rate is correct | Y17: As Expected | Z17: Passed | AA17: Automation | AC17: =HYPERLINK("Screenshots/Wing Wei Luy/TCRT-0013","View Screenshots") -> View Screenshots | AD17: 70438333
A18: 14 | B18: TCRT-0014 | E18: Perfrom from FC KHR to Phone Number | F18: Normal | G18: Perfrom from FC KHR to Phone Number | H18: FC | I18: =IF(H18="PSP",IF(K18="KHR",'Config Data'!$D$13,'Config Data'!$D$14),IF(H18="FC",IF(K18="KHR",'Config Data'!$D$15,'Config Data'!$D$16))) -> 103634567 | J18: High Yield Saving - Standard | K18: KHR | L18: =IF(K18="KHR",'Config Data'!$D$21,IF(K18="USD",'Config Data'!$D$23,"")) -> 120000 | M18: 3000 | N18: 0 | O18: 120000 | P18: Phone Number | Q18: ='Config Data'!D$17 -> 077989682 | R18: N/A | S18: N/A | U18: N/A | V18: 0002343262390011 | W18: 27-08-2026 | 01:55:38 AM | X18: 1-Transaction will be success 2-Amount deducted from the payer to the payee is correct 3-Exchange rate is correct | Y18: As Expected | Z18: Passed | AA18: Automation | AC18: =HYPERLINK("Screenshots/Wing Wei Luy/TCRT-0014","View Screenshots") -> View Screenshots | AD18: 35399830
A19: 15 | B19: TCRT-0015 | E19: Perfrom from FC USD to Phone Number | F19: Normal | G19: Perfrom from FC USD to Phone Number | H19: FC | I19: =IF(H19="PSP",IF(K19="KHR",'Config Data'!$D$13,'Config Data'!$D$14),IF(H19="FC",IF(K19="KHR",'Config Data'!$D$15,'Config Data'!$D$16))) -> 103634533 | J19: High Yield Saving - Standard | K19: USD | L19: =IF(K19="KHR",'Config Data'!$D$21,IF(K19="USD",'Config Data'!$D$23,"")) -> 30 | M19: 0.75 | N19: 0 | O19: 30.00 | P19: Phone Number | Q19: ='Config Data'!D$17 -> 077989682 | R19: N/A | S19: N/A | U19: N/A | V19: 0002343262390012 | W19: 27-08-2026 | 01:56:05 AM | X19: 1-Transaction will be success 2-Amount deducted from the payer to the payee is correct 3-Exchange rate is correct | Y19: As Expected | Z19: Passed | AA19: Automation | AC19: =HYPERLINK("Screenshots/Wing Wei Luy/TCRT-0015","View Screenshots") -> View Screenshots | AD19: 14405939
A20: 16 | B20: TCRT-0016 | E20: Perfrom from PSP KHR to Phone Number | F20: Normal | G20: Perfrom from PSP KHR to Phone Number | H20: PSP | I20: =IF(H20="PSP",IF(K20="KHR",'Config Data'!$D$13,'Config Data'!$D$14),IF(H20="FC",IF(K20="KHR",'Config Data'!$D$15,'Config Data'!$D$16))) -> 07782083 | J20: High Yield Saving - Standard | K20: KHR | L20: =IF(K20="KHR",'Config Data'!$D$21,IF(K20="USD",'Config Data'!$D$23,"")) -> 120000 | M20: 3000 | N20: 0 | O20: 120000 | P20: Phone Number | Q20: ='Config Data'!D$17 -> 077989682 | R20: N/A | S20: N/A | U20: N/A | V20: AYZ539470 | W20: 27-08-2026 | 01:56:39 AM | X20: 1-Transaction will be success 2-Amount deducted from the payer to the payee is correct 3-Exchange rate is correct | Y20: As Expected | Z20: Passed | AA20: Automation | AC20: =HYPERLINK("Screenshots/Wing Wei Luy/TCRT-0016","View Screenshots") -> View Screenshots | AD20: 58243802
A21: 17 | B21: TCRT-0017 | D21: Code to Wing | E21: Perform code to non-Wing to FC KHR that performed wwl from PSP USD (cross currency) | F21: Normal | G21: Perform code to non-Wing to FC KHR that performed wwl from PSP USD (cross currency) | H21: PSP | I21: =IF(H21="PSP",IF(K21="KHR",'Config Data'!$D$13,'Config Data'!$D$14),IF(H21="FC",IF(K21="KHR",'Config Data'!$D$15,'Config Data'!$D$16))) -> 07782087 | J21: Customer - Current Account Personal - Standard | K21: USD | L21: =IF(K21="KHR",'Config Data'!$D$21,IF(K21="USD",'Config Data'!$D$23,"")) -> 30 | M21: 0 | N21: 0 | O21: 121350 | P21: FC | Q21: =IF(P21="PSP",IF(S21="KHR",'Config Data'!$D$13,'Config Data'!$D$14),IF(P21="FC",IF(S21="KHR",'Config Data'!$D$15,'Config Data'!$D$16))) -> 103634567 | R21: High Yield Saving - Standard | S21: KHR | U21: Small Rate | V21: GYQ687350 | W21: 27-08-2026 | 01:57:10 AM | X21: 1-Transaction will be success 2-Amount deducted from the payer to the payee is correct 3-Exchange rate is correct | Y21: As Expected | Z21: Passed | AA21: Automation | AC21: =HYPERLINK("Screenshots/Code to Wing/TCRT-0017","View Screenshots") -> View Screenshots
A22: 18 | B22: TCRT-0018 | E22: Perform code to non-Wing to PSP USD that performed wwl from FC KHR (cross currency) | F22: Normal | G22: Perform code to wing to PSP USD that performed wwl from FC KHR (cross currency) | H22: FC | I22: =IF(H22="PSP",IF(K22="KHR",'Config Data'!$D$13,'Config Data'!$D$14),IF(H22="FC",IF(K22="KHR",'Config Data'!$D$15,'Config Data'!$D$16))) -> 103634567 | J22: High Yield Saving - Standard | K22: KHR | L22: =IF(K22="KHR",'Config Data'!$D$21,IF(K22="USD",'Config Data'!$D$23,"")) -> 120000 | M22: 0 | N22: 0 | O22: 29.60 | P22: PSP | Q22: =IF(P22="PSP",IF(S22="KHR",'Config Data'!$D$13,'Config Data'!$D$14),IF(P22="FC",IF(S22="KHR",'Config Data'!$D$15,'Config Data'!$D$16))) -> 07782087 | R22: Customer - Current Account Personal - Standard | S22: USD | U22: Big Rate | V22: GYQ687352 | W22: 27-08-2026 | 01:57:39 AM | X22: 1-Transaction will be success 2-Amount deducted from the payer to the payee is correct 3-Exchange rate is correct | Y22: As Expected | Z22: Passed | AA22: Automation | AC22: =HYPERLINK("Screenshots/Code to Wing/TCRT-0018","View Screenshots") -> View Screenshots
A23: 19 | B23: TCRT-0019 | E23: Perform code to non-Wing to PSP KHR that performed wwl from FC USD (cross currency) | F23: Normal | G23: Perform code to wing to PSP KHR that performed wwl from FC USD (cross currency) | H23: FC | I23: =IF(H23="PSP",IF(K23="KHR",'Config Data'!$D$13,'Config Data'!$D$14),IF(H23="FC",IF(K23="KHR",'Config Data'!$D$15,'Config Data'!$D$16))) -> 103634533 | J23: High Yield Saving - Standard | K23: USD | L23: =IF(K23="KHR",'Config Data'!$D$21,IF(K23="USD",'Config Data'!$D$23,"")) -> 30 | M23: 0 | N23: 0 | O23: 121350 | P23: PSP | Q23: =IF(P23="PSP",IF(S23="KHR",'Config Data'!$D$13,'Config Data'!$D$14),IF(P23="FC",IF(S23="KHR",'Config Data'!$D$15,'Config Data'!$D$16))) -> 07782083 | R23: Customer - Current Account Personal - Standard | S23: KHR | U23: Small Rate | V23: GYQ687353 | W23: 27-08-2026 | 01:58:10 AM | X23: 1-Transaction will be success 2-Amount deducted from the payer to the payee is correct 3-Exchange rate is correct | Y23: As Expected | Z23: Passed | AA23: Automation | AC23: =HYPERLINK("Screenshots/Code to Wing/TCRT-0019","View Screenshots") -> View Screenshots
A24: 20 | B24: TCRT-0020 | E24: Perform code to non-Wing to FC USD that performed wwl from PSP KHR (cross currency) | F24: Normal | G24: Perform code to wing to FC USD that performed wwl from PSP KHR (cross currency) | H24: PSP | I24: =IF(H24="PSP",IF(K24="KHR",'Config Data'!$D$13,'Config Data'!$D$14),IF(H24="FC",IF(K24="KHR",'Config Data'!$D$15,'Config Data'!$D$16))) -> 07782083 | J24: Customer - Current Account Personal - Standard | K24: KHR | L24: =IF(K24="KHR",'Config Data'!$D$21,IF(K24="USD",'Config Data'!$D$23,"")) -> 120000 | M24: 0 | N24: 0 | O24: 29.61 | P24: FC | Q24: =IF(P24="PSP",IF(S24="KHR",'Config Data'!$D$13,'Config Data'!$D$14),IF(P24="FC",IF(S24="KHR",'Config Data'!$D$15,'Config Data'!$D$16))) -> 103634533 | R24: High Yield Saving - Standard | S24: USD | U24: Big Rate | V24: GYQ687354 | W24: 27-08-2026 | 01:58:39 AM | X24: 1-Transaction will be success 2-Amount deducted from the payer to the payee is correct 3-Exchange rate is correct | Y24: As Expected | Z24: Passed | AA24: Automation | AC24: =HYPERLINK("Screenshots/Code to Wing/TCRT-0020","View Screenshots") -> View Screenshots
A25: 21 | B25: TCRT-0021 | D25: PTU Pinless | E25: Peform from PSP USD to Smart | F25: Normal | G25: Peform from PSP USD to Smart | H25: PSP | I25: =IF(H25="PSP",IF(K25="KHR",'Config Data'!$D$13,'Config Data'!$D$14),IF(H25="FC",IF(K25="KHR",'Config Data'!$D$15,'Config Data'!$D$16))) -> 07782087 | J25: Customer - Current Account Personal - Standard | K25: USD | L25: 1.00 | M25: 0 | N25: 0 | O25: 1 | P25: Phone Number | Q25: =IF(R25="Smart",'Config Data'!D$44,IF(R25="Cellcard",'Config Data'!D$45,"")) -> 098229845 | R25: Smart | S25: USD | U25: N/A | V25: HTS558722 | W25: 27-08-2026 | 01:59:05 AM | X25: 1-Transaction will be success 2-Amount deducted from the payer to the payee is correct 3-Exchange rate is correct | Y25: As Expected | Z25: Passed | AA25: Automation | AC25: =HYPERLINK("Screenshots/PTU Pinless/TCRT-0021","View Screenshots") -> View Screenshots
A26: 22 | B26: TCRT-0022 | E26: Peform from FC KHR to Smart (cross currency) | F26: Normal | G26: Peform from FC KHR to Smart (cross currency) | H26: FC | I26: =IF(H26="PSP",IF(K26="KHR",'Config Data'!$D$13,'Config Data'!$D$14),IF(H26="FC",IF(K26="KHR",'Config Data'!$D$15,'Config Data'!$D$16))) -> 103634567 | J26: High Yield Saving - Standard | K26: KHR | L26: 4053 | M26: 0 | N26: 0 | O26: 1 | P26: Phone Number | Q26: =IF(R26="Smart",'Config Data'!D$44,IF(R26="Cellcard",'Config Data'!D$45,"")) -> 098229845 | R26: Smart | S26: USD | U26: Big Rate | V26: 0002381262390739 | W26: 27-08-2026 | 01:59:27 AM | X26: 1-Transaction will be success 2-Amount deducted from the payer to the payee is correct 3-Exchange rate is correct | Y26: As Expected | Z26: Passed | AA26: Automation | AC26: =HYPERLINK("Screenshots/PTU Pinless/TCRT-0022","View Screenshots") -> View Screenshots
A27: 23 | B27: TCRT-0023 | E27: Peform from FC USD to Cellcard | F27: Normal | G27: Peform from FC USD to Cellcard | H27: FC | I27: =IF(H27="PSP",IF(K27="KHR",'Config Data'!$D$13,'Config Data'!$D$14),IF(H27="FC",IF(K27="KHR",'Config Data'!$D$15,'Config Data'!$D$16))) -> 103634533 | J27: High Yield Saving - Standard | K27: USD | L27: 1.00 | M27: 0 | N27: 0 | O27: 1 | P27: Phone Number | Q27: =IF(R27="Smart",'Config Data'!D$44,IF(R27="Cellcard",'Config Data'!D$45,"")) -> 078731099 | R27: Cellcard | S27: USD | U27: N/A | V27: 0002381262390742 | W27: 27-08-2026 | 01:59:48 AM | X27: 1-Transaction will be success 2-Amount deducted from the payer to the payee is correct 3-Exchange rate is correct | Y27: As Expected | Z27: Passed | AA27: Automation | AC27: =HYPERLINK("Screenshots/PTU Pinless/TCRT-0023","View Screenshots") -> View Screenshots
A28: 24 | B28: TCRT-0024 | D28: PTU PIN | E28: Perform from PSP KHR to Smart (cross currency) | F28: Normal | G28: Perform from PSP KHR to Smart (cross currency) | H28: PSP | I28: =IF(H28="PSP",IF(K28="KHR",'Config Data'!$D$13,'Config Data'!$D$14),IF(H28="FC",IF(K28="KHR",'Config Data'!$D$15,'Config Data'!$D$16))) -> 07782083 | J28: Customer - Current Account Personal - Standard | K28: KHR | L28: 4053 | M28: 0 | N28: 0 | O28: 1 | P28: Operator | Q28: Smart | R28: N/A | S28: USD | U28: Big Rate | V28: HTS558746 | W28: 27-08-2026 | 02:00:08 AM | X28: 1-Transaction will be success 2-Amount deducted from the payer to the payee is correct 3-Exchange rate is correct | Y28: As Expected | Z28: Passed | AA28: Automation | AC28: =HYPERLINK("Screenshots/PTU PIN/TCRT-0024","View Screenshots") -> View Screenshots
A29: 25 | B29: TCRT-0025 | E29: Perform from FC USD to Cellcard | F29: Normal | G29: Perform from FC USD to Cellcard | H29: FC | I29: =IF(H29="PSP",IF(K29="KHR",'Config Data'!$D$13,'Config Data'!$D$14),IF(H29="FC",IF(K29="KHR",'Config Data'!$D$15,'Config Data'!$D$16))) -> 103634533 | J29: High Yield Saving - Standard | K29: USD | L29: 1.00 | M29: 0 | N29: 0 | O29: 1 | P29: Operator | Q29: Cellcard | R29: N/A | S29: USD | U29: N/A | V29: 0002382262390018 | W29: 27-08-2026 | 02:00:27 AM | X29: 1-Transaction will be success 2-Amount deducted from the payer to the payee is correct 3-Exchange rate is correct | Y29: As Expected | Z29: Passed | AA29: Automation | AC29: =HYPERLINK("Screenshots/PTU PIN/TCRT-0025","View Screenshots") -> View Screenshots
A30: 26 | B30: TCRT-0026 | D30: KHQR(WingBank to customer other bank) | E30: Perform from PSP KHR to customer of other bank USD (scan khqr) (cross currency) | F30: Normal | G30: Perform from PSP KHR to customer of other bank USD (scan khqr) (cross currency) | H30: PSP | I30: =IF(H30="PSP",IF(K30="KHR",'Config Data'!$D$13,'Config Data'!$D$14),IF(H30="FC",IF(K30="KHR",'Config Data'!$D$15,'Config Data'!$D$16))) -> 07782083 | J30: Customer - Current Account Personal - Standard | K30: KHR | L30: 121590 | M30: 0 | N30: 0 | O30: =IF(AND(K30="USD",S30="KHR"),120000,IF(AND(K30="KHR",S30="USD"),30,IF(AND(K30="USD",S30="USD"),1,IF(AND(K30="KHR",S30="KHR"),4000,IF(S30="KHR",'Config Data'!$D$21,IF(S30="USD",'Config Data'!$D$23,"")))))) -> 30 | P30: Customer QR OtherBank | Q30: =IF('Config Data'!B29=FALSE,IF(P30="Customer QR OtherBank",IF(S30="KHR",'Config Data'!E$39,'Config Data'!E$38)),IF(P30="Customer QR OtherBank",IF(S30="KHR",'Config Data'!D$39,'Config Data'!D$38))) -> 00020101021229450016abaakhppxxx@abaa01090044268570208ABA Bank40390006abaP2P011259D64CDECE0F02090044268575204000053038405402305802KH5909RORN MONY6010Phnom Penh993400131776671446325011318082074463256304E369 | R30: ABA Bank Customer | S30: USD | U30: Big Rate | V30: QBF957327 | W30: 27-08-2026 | 02:00:55 AM | X30: 1-Transaction will be success 2-Amount deducted from the payer to the payee is correct 3-Exchange rate is correct | Y30: As Expected | Z30: Passed | AA30: Automation | AC30: =HYPERLINK("Screenshots/KHQR (WingBank to Customer Other Bank)/TCRT-0026","View Screenshots") -> View Screenshots
A31: 27 | B31: TCRT-0027 | E31: Perform from FC USD to customer of other bank KHR (scan khqr) (cross currency) | F31: Normal | G31: Perform from FC USD to customer of other bank KHR (scan khqr) (cross currency) | H31: FC | I31: =IF(H31="PSP",IF(K31="KHR",'Config Data'!$D$13,'Config Data'!$D$14),IF(H31="FC",IF(K31="KHR",'Config Data'!$D$15,'Config Data'!$D$16))) -> 103634533 | J31: High Yield Saving - Standard | K31: USD | L31: 29.67 | M31: 0 | N31: 0 | O31: =IF(AND(K31="USD",S31="KHR"),120000,IF(AND(K31="KHR",S31="USD"),30,IF(AND(K31="USD",S31="USD"),1,IF(AND(K31="KHR",S31="KHR"),4000,IF(S31="KHR",'Config Data'!$D$21,IF(S31="USD",'Config Data'!$D$23,"")))))) -> 120000 | P31: Customer QR OtherBank | Q31: =IF('Config Data'!B29=FALSE,IF(P31="Customer QR OtherBank",IF(S31="KHR",'Config Data'!E$39,'Config Data'!E$38)),IF(P31="Customer QR OtherBank",IF(S31="KHR",'Config Data'!D$39,'Config Data'!D$38))) -> 00020101021229450016abaakhppxxx@abaa01096009011050208ABA Bank40390006abaP2P011259D64CDECE0F020960090110552040000530311654061200005802KH5909RORN MONY6010Phnom Penh9934001317766714861950113180820748619563041F76 | R31: ABA Bank Customer | S31: KHR | U31: Small Rate | V31: 0002347262396109 | W31: 27-08-2026 | 02:01:24 AM | X31: 1-Transaction will be success 2-Amount deducted from the payer to the payee is correct 3-Exchange rate is correct | Y31: As Expected | Z31: Passed | AA31: Automation | AC31: =HYPERLINK("Screenshots/KHQR (WingBank to Customer Other Bank)/TCRT-0027","View Screenshots") -> View Screenshots
A32: 28 | B32: TCRT-0028 | D32: QR Pay | E32: Perform from PSP KHR to merchant PSP USD(no point) via scan KHQR of wingPay (cross currency) | F32: Normal | G32: Perform from PSP KHR to merchant PSP USD(no point) via scan KHQR of wingPay (cross currency) | H32: PSP | I32: =IF(H32="PSP",IF(K32="KHR",'Config Data'!$D$13,'Config Data'!$D$14),IF(H32="FC",IF(K32="KHR",'Config Data'!$D$15,'Config Data'!$D$16))) -> 07782083 | J32: Customer - Current Account Personal - Standard | K32: KHR | L32: 121590 | M32: 0 | N32: 0 | O32: =IF(AND(K32="USD",S32="KHR"),120000,IF(AND(K32="KHR",S32="USD"),30,IF(AND(K32="USD",S32="USD"),1,IF(AND(K32="KHR",S32="KHR"),4000,IF(S32="KHR",'Config Data'!$D$21,IF(S32="USD",'Config Data'!$D$23,"")))))) -> 30 | P32: Merchant App PSP | Q32: =IF('Config Data'!$B$29=FALSE,IF(P32="Merchant App PSP",IF(S32="KHR",'Config Data'!$E$34,'Config Data'!$E$35),IF(P32="Merchant App FC",IF(S32="KHR",'Config Data'!$E$33,'Config Data'!$E$32))),IF(P32="Merchant App PSP",IF(S32="KHR",'Config Data'!$D$34,'Config Data'!$D$35),IF(P32="Merchant App FC",IF(S32="KHR",'Config Data'!$D$33,'Config Data'!$D$32)))) -> 00020101021130510014wing_khqr@wing01065331350207WINGPAY0308MERCHANT5204721153038405802KH5923PMOTest Youhai Ren Shop6010Phnom Penh6105120006304B296 | R32: Retail - Bill Pay Corp I (Fee Free) | S32: USD | T32: 4053 | U32: Big Rate | V32: JBT758234 | W32: 27-08-2026 | 02:01:50 AM | X32: 1-Transaction will be success 2-Amount deducted from the payer to the payee is correct 3-Exchange rate is correct | Y32: As Expected | Z32: Passed | AA32: Automation | AC32: =HYPERLINK("Screenshots/QR Pay (Scan)/TCRT-0028","View Screenshots") -> View Screenshots
A33: 29 | B33: TCRT-0029 | E33: Perform from PSP USD to merchant corp1 FC KHR(have point) via scan KHQR of wingPay (cross currency) | F33: Normal | G33: Perform from PSP USD to merchant corp1 FC KHR(have point) via scan KHQR of wingPay (cross currency) | H33: PSP | I33: =IF(H33="PSP",IF(K33="KHR",'Config Data'!$D$13,'Config Data'!$D$14),IF(H33="FC",IF(K33="KHR",'Config Data'!$D$15,'Config Data'!$D$16))) -> 07782087 | J33: Customer - Current Account Personal - Standard | K33: USD | L33: 29.66 | M33: 3000 | N33: 0 | O33: =IF(AND(K33="USD",S33="KHR"),120000,IF(AND(K33="KHR",S33="USD"),30,IF(AND(K33="USD",S33="USD"),1,IF(AND(K33="KHR",S33="KHR"),4000,IF(S33="KHR",'Config Data'!$D$21,IF(S33="USD",'Config Data'!$D$23,"")))))) -> 120000 | P33: Merchant App FC | Q33: =IF('Config Data'!$B$29=FALSE,IF(P33="Merchant App PSP",IF(S33="KHR",'Config Data'!$E$34,'Config Data'!$E$35),IF(P33="Merchant App FC",IF(S33="KHR",'Config Data'!$E$33,'Config Data'!$E$32))),IF(P33="Merchant App PSP",IF(S33="KHR",'Config Data'!$D$34,'Config Data'!$D$35),IF(P33="Merchant App FC",IF(S33="KHR",'Config Data'!$D$33,'Config Data'!$D$32)))) -> 00020101021130420014wing_khqr@wing01090001342930207WINGPAY5204599953031165802KH5919PMOTEST HAI CAR SOP6010Phnom Penh624401062571730211855959890720715FCCMPY00035927863047A8A | R33: Loyalty - Corp 1 (MDR: 0% + Bronze: 2.5%) | S33: KHR | T33: 4045 | U33: Small Rate | V33: JBT758273 | W33: 27-08-2026 | 02:02:21 AM | X33: 1-Transaction will be success 2-Amount deducted from the payer to the payee is correct 3-Exchange rate is correct | Y33: As Expected | Z33: Passed | AA33: Automation | AC33: =HYPERLINK("Screenshots/QR Pay (Scan)/TCRT-0029","View Screenshots") -> View Screenshots
A34: 30 | B34: TCRT-0030 | E34: Perform from PSP KHR to merchant corp1 FC USD(no point) via scan KHQR of wingpay (cross currency) | F34: Normal | G34: Perform from PSP KHR to merchant corp1 FC USD(no point) via scan KHQR of wingpay (cross currency) | H34: PSP | I34: =IF(H34="PSP",IF(K34="KHR",'Config Data'!$D$13,'Config Data'!$D$14),IF(H34="FC",IF(K34="KHR",'Config Data'!$D$15,'Config Data'!$D$16))) -> 07782083 | J34: Customer - Current Account Personal - Standard | K34: KHR | L34: 121590 | M34: 0 | N34: 0 | O34: =IF(AND(K34="USD",S34="KHR"),120000,IF(AND(K34="KHR",S34="USD"),30,IF(AND(K34="USD",S34="USD"),1,IF(AND(K34="KHR",S34="KHR"),4000,IF(S34="KHR",'Config Data'!$D$21,IF(S34="USD",'Config Data'!$D$23,"")))))) -> 30 | P34: Merchant App FC | Q34: =IF('Config Data'!$B$29=FALSE,IF(P34="Merchant App PSP",IF(S34="KHR",'Config Data'!$E$34,'Config Data'!$E$35),IF(P34="Merchant App FC",IF(S34="KHR",'Config Data'!$E$33,'Config Data'!$E$32))),IF(P34="Merchant App PSP",IF(S34="KHR",'Config Data'!$D$34,'Config Data'!$D$35),IF(P34="Merchant App FC",IF(S34="KHR",'Config Data'!$D$33,'Config Data'!$D$32)))) -> 00020101021130420014wing_khqr@wing01090001342930207WINGPAY5204599953031165802KH5919PMOTEST HAI CAR SOP6010Phnom Penh624401062571730211855959890720715FCCMPY00035927863047A8A | R34: Loyalty - (MDR: 0% + Standard_low: 0%) | S34: USD | T34: 4053 | U34: Big Rate | V34: JBT758311 | W34: 27-08-2026 | 02:02:47 AM | X34: 1-Transaction will be success 2-Amount deducted from the payer to the payee is correct 3-Exchange rate is correct | Y34: As Expected | Z34: Passed | AA34: Automation | AC34: =HYPERLINK("Screenshots/QR Pay (Scan)/TCRT-0030","View Screenshots") -> View Screenshots
A35: 31 | B35: TCRT-0031 | E35: Perform from FC KHR to merchant PSP USD(no point) via scan KHQR of wingpay (cross currency) | F35: Normal | G35: Perform from FC KHR to merchant PSP USD(no point) via scan KHQR of wingpay (cross currency) | H35: FC | I35: =IF(H35="PSP",IF(K35="KHR",'Config Data'!$D$13,'Config Data'!$D$14),IF(H35="FC",IF(K35="KHR",'Config Data'!$D$15,'Config Data'!$D$16))) -> 103634567 | J35: High Yield Saving - Standard | K35: KHR | L35: 121590 | M35: 0 | N35: 0 | O35: =IF(AND(K35="USD",S35="KHR"),120000,IF(AND(K35="KHR",S35="USD"),30,IF(AND(K35="USD",S35="USD"),1,IF(AND(K35="KHR",S35="KHR"),4000,IF(S35="KHR",'Config Data'!$D$21,IF(S35="USD",'Config Data'!$D$23,"")))))) -> 30 | P35: Merchant App PSP | Q35: =IF('Config Data'!$B$29=FALSE,IF(P35="Merchant App PSP",IF(S35="KHR",'Config Data'!$E$34,'Config Data'!$E$35),IF(P35="Merchant App FC",IF(S35="KHR",'Config Data'!$E$33,'Config Data'!$E$32))),IF(P35="Merchant App PSP",IF(S35="KHR",'Config Data'!$D$34,'Config Data'!$D$35),IF(P35="Merchant App FC",IF(S35="KHR",'Config Data'!$D$33,'Config Data'!$D$32)))) -> 00020101021130510014wing_khqr@wing01065331350207WINGPAY0308MERCHANT5204721153038405802KH5923PMOTest Youhai Ren Shop6010Phnom Penh6105120006304B296 | R35: Retail - Bill Pay Corp I (Fee Free) | S35: USD | T35: 4053 | U35: Big Rate | V35: 0002448262390008 | W35: 27-08-2026 | 02:03:15 AM | X35: 1-Transaction will be success 2-Amount deducted from the payer to the payee is correct 3-Exchange rate is correct | Y35: As Expected | Z35: Passed | AA35: Automation | AC35: =HYPERLINK("Screenshots/QR Pay (Scan)/TCRT-0031","View Screenshots") -> View Screenshots
A36: 32 | B36: TCRT-0032 | E36: Perform from FC USD to merchant corp1 FC KHR(have point) via scan KHQR of wingpay (cross currency) | F36: Normal | G36: Perform from FC USD to merchant corp1 FC KHR(have point) via scan KHQR of wingpay (cross currency) | H36: FC | I36: =IF(H36="PSP",IF(K36="KHR",'Config Data'!$D$13,'Config Data'!$D$14),IF(H36="FC",IF(K36="KHR",'Config Data'!$D$15,'Config Data'!$D$16))) -> 103634533 | J36: High Yield Saving - Standard | K36: USD | L36: 29.67 | M36: 3000 | N36: 0 | O36: =IF(AND(K36="USD",S36="KHR"),120000,IF(AND(K36="KHR",S36="USD"),30,IF(AND(K36="USD",S36="USD"),1,IF(AND(K36="KHR",S36="KHR"),4000,IF(S36="KHR",'Config Data'!$D$21,IF(S36="USD",'Config Data'!$D$23,"")))))) -> 120000 | P36: Merchant App FC | Q36: =IF('Config Data'!$B$29=FALSE,IF(P36="Merchant App PSP",IF(S36="KHR",'Config Data'!$E$34,'Config Data'!$E$35),IF(P36="Merchant App FC",IF(S36="KHR",'Config Data'!$E$33,'Config Data'!$E$32))),IF(P36="Merchant App PSP",IF(S36="KHR",'Config Data'!$D$34,'Config Data'!$D$35),IF(P36="Merchant App FC",IF(S36="KHR",'Config Data'!$D$33,'Config Data'!$D$32)))) -> 00020101021130420014wing_khqr@wing01090001342930207WINGPAY5204599953031165802KH5919PMOTEST HAI CAR SOP6010Phnom Penh624401062571730211855959890720715FCCMPY00035927863047A8A | R36: Loyalty - Corp 1 (MDR: 0% + Bronze: 2.5%) | S36: KHR | T36: 4045 | U36: Small Rate | V36: 0002476262390394 | W36: 27-08-2026 | 02:03:42 AM | X36: 1-Transaction will be success 2-Amount deducted from the payer to the payee is correct 3-Exchange rate is correct | Y36: As Expected | Z36: Passed | AA36: Automation | AC36: =HYPERLINK("Screenshots/QR Pay (Scan)/TCRT-0032","View Screenshots") -> View Screenshots
